---
layout: post
title: C++异常处理
date: 2018-07-29 22:00:24.000000000 +08:00
---

C++异常是指在程序运行时发生的特殊情况，比如尝试除以零的操作。异常提供了一种转移程序控制权的方式。C++异常处理涉及到三个关键字：`try`、`catch`、`throw`。

- throw：问题出现时，使用throw让程序抛出一个异常。
- catch：在想要处理问题的地方，通过catch来捕获异常。
- try：用于放置可能抛出异常的代码，这些代码被称为保护代码，后面常接catch代码块用于捕获抛出的异常。

使用 try/catch 语句的语法如下所示：

	try
	{
		//保护代码
	}catch( ExceptionName e1)
	{
		//catch块
	}catch( ExceptionName e2)
	{
		//catch块
	}

如果try块在不同的情境下会抛出不同的异常，这个时候可以尝试罗列多个 catch 语句，用于捕获不同类型的异常。

**抛出异常**

可以使用throw语句在代码块的任意位置抛出异常，操作数可以是任意表达式，表达式的结果类型决定了抛出的异常类型。

	double division(int a, int b)
	{
		if(b==0)
		{
			throw "Division by zero condition";
		}
		return (a/b);
	}

**捕获异常**

在介绍try/catch异常时我们就介绍了如何捕获异常。如果想让catch能够处理try块抛出的任何类型异常，必须在异常声明括号内使用省略号(...):

	try
	{
		//保护代码
	}catch(...)
	{
		//能处理任何异常的代码
	}

**C++标准的异常**

C++ 提供了一系列标准的异常，定义在 < exception > 中，我们可以在程序中使用这些标准的异常。它们是以父子类层次结构组织起来的，如下所示：

![Alt text](https://github.com/GitCatRyan/gitcatryan.github.io/raw/master/assets/images/cpp_exceptions.jpg)

- std::exception：该异常是所有标准 C++ 异常的父类。
- std::bad_alloc：该异常可以通过 new 抛出。
- std::bad_cast：该异常可以通过 dynamic_cast 抛出。
- std::bad_exception：这在处理C++程序中无法预期的异常时非常有用。
- std::bad_typeid：该异常可以通过 typeid 抛出。
- std::logic_error：理论上可以通过读取代码来检测到的异常。
- std::domain_error：当使用了一个无效的数学域时，会抛出该异常。
- std::invalid_argument：当使用了无效的参数时，会抛出该异常。
- std::length_error：当创建了太长的 std::string 时，会抛出该异常。
- std::out_of_range：该异常可以通过方法抛出，例如 std::vector 和 std::bitset<>::operator[]()。
- std::runtime_error：理论上不可以通过读取代码来检测到的异常。
- std::overflow_error：当发生数学上溢时，会抛出该异常。
- std::range_error：当尝试存储超出范围的值时，会抛出该异常。
- std::underflow_error：当发生数学下溢时，会抛出该异常。

**定义新的异常**

可以通过继承和重载`exception`类来定义新的异常。

	#include <iostream>
	#include <exception>
	using namespace std;
 
	struct MyException : public exception 	//继承
	{
		const char * what () const throw ()
		{
    	return "C++ Exception";
		}
	};
 
	int main()
	{
		try
		{
			throw MyException();
		}
		catch(MyException& e)
		{
    		std::cout << "MyException caught" << std::endl;
    		std::cout << e.what() << std::endl;
		}
		catch(std::exception& e)
		{
			//其他的错误
		}
	}

在这里，`what()`是异常类提供的一个公共方法，它已被所有子异常类重载。这将返回异常产生的原因。

`const throw()`不是函数，这个东西叫异常规格说明，表示 what 函数可以抛出异常的类型，类型说明放到 () 里，这里面没有类型，就是声明这个函数不抛出异常，通常函数不写后面的就表示函数可以抛出任何类型的异常。
